<?xml version="1.0" ?>
<!-- =================================================================================== -->
<!-- |    This document was autogenerated by xacro from ls.xacro                       | -->
<!-- |    EDITING THIS FILE BY HAND IS NOT RECOMMENDED                                 | -->
<!-- =================================================================================== -->
<robot name="mobile_manipulator">
  <gazebo>
    <plugin filename="libgazebo_ros_control.so" name="gazebo_ros_control">
      <robotNamespace>/</robotNamespace>
      <robotSimType>gazebo_ros_control/DefaultRobotHWSim</robotSimType>
      <legacyModeNs>true</legacyModeNs>
    </plugin>
  </gazebo>
  <link name="base_footprint">
    <visual>
      <origin rpy="0 0 0" xyz="0 0 0"/>
      <geometry>
        <box size="0.001 0.001 0.001"/>
      </geometry>
    </visual>
  </link>
  <link name="left_body">
    <inertial>
      <mass value="1"/>
      <inertia ixx="0.0250083333333" ixy="0" ixz="0" iyy="0.0241666666667" iyz="0" izz="0.0425083333333"/>
    </inertial>
    <visual>
      <geometry>
        <!-- <box size="0.4 0.151 0.15"/> -->
        <mesh filename="package://mm_description/meshes/vehicle/track_entity_meter.STL"/>
      </geometry>
    </visual>
    <collision>
      <geometry>
        <box size="0.4 0.151 0.15"/>
      </geometry>
    </collision>
  </link>
  <gazebo reference="left_body">
    <material>Gazebo/DarkGrey</material>
  </gazebo>
  <gazebo reference="left_body_fixed_idler_link_1">
    <material>Gazebo/DarkGrey</material>
  </gazebo>
  <gazebo reference="left_body_fixed_idler_link_2">
    <material>Gazebo/DarkGrey</material>
  </gazebo>
  <gazebo reference="left_body_fixed_idler_link_3">
    <material>Gazebo/DarkGrey</material>
  </gazebo>
  <gazebo reference="left_sprocket">
    <material>Gazebo/DarkGrey</material>
  </gazebo>
  <!-- body cylinder: back-->
  <link name="left_body_fixed_idler_link_1">
    <inertial>
      <mass value="0.2"/>
      <inertia ixx="0.004655" ixy="0" ixz="0" iyy="0.00064" iyz="0" izz="0.004655"/>
    </inertial>
    <visual>
      <origin rpy="1.57079632679 0 0" xyz="0 0 0"/>
      <geometry>
        <cylinder length="0.15" radius="0.08"/>
      </geometry>
    </visual>
    <collision>
      <origin rpy="1.57079632679 0 0" xyz="0 0 0"/>
      <geometry>
        <cylinder length="0.15" radius="0.08"/>
      </geometry>
    </collision>
  </link>
  <joint name="left_body_fixed_idler_joint_1" type="fixed">
    <origin rpy="0 0 0" xyz="-0.36 0 0"/>
    <parent link="left_body"/>
    <child link="left_body_fixed_idler_link_1"/>
  </joint>
  <!-- body cylinder: front-->
  <link name="left_body_fixed_idler_link_2">
    <inertial>
      <mass value="0.2"/>
      <inertia ixx="0.004655" ixy="0" ixz="0" iyy="0.00064" iyz="0" izz="0.004655"/>
    </inertial>
    <visual>
      <origin rpy="1.57079632679 0 0" xyz="0 0 0"/>
      <geometry>
        <cylinder length="0.15" radius="0.07"/>
      </geometry>
    </visual>
    <collision>
      <origin rpy="1.57079632679 0 0" xyz="0 0 0"/>
      <geometry>
        <cylinder length="0.15" radius="0.07"/>
      </geometry>
    </collision>
  </link>
  <joint name="left_body_fixed_idler_joint_2" type="fixed">
    <origin rpy="0 0 0" xyz="0.445 0 0.102"/>
    <parent link="left_body"/>
    <child link="left_body_fixed_idler_link_2"/>
  </joint>
  <!-- body cylinder: top-->
  <link name="left_body_fixed_idler_link_3">
    <inertial>
      <mass value="0.2"/>
      <inertia ixx="0.004655" ixy="0" ixz="0" iyy="0.00064" iyz="0" izz="0.004655"/>
    </inertial>
    <visual>
      <origin rpy="1.57079632679 0 0" xyz="0 0 0"/>
      <geometry>
        <cylinder length="0.15" radius="0.062"/>
      </geometry>
    </visual>
    <collision>
      <origin rpy="1.57079632679 0 0" xyz="0 0 0"/>
      <geometry>
        <cylinder length="0.15" radius="0.062"/>
      </geometry>
    </collision>
  </link>
  <joint name="left_body_fixed_idler_joint_3" type="fixed">
    <origin rpy="0 0 0" xyz="0.00953 0 0.16618"/>
    <parent link="left_body"/>
    <child link="left_body_fixed_idler_link_3"/>
  </joint>
  <!-- sprocket driving the track : cylinder -->
  <link name="left_sprocket">
    <inertial>
      <mass value="0.2"/>
      <!-- assuming axis of cylinder is y, not z -->
      <inertia ixx="0.004655" ixy="0" ixz="0" iyy="0.00064" iyz="0" izz="0.004655"/>
    </inertial>
    <visual>
      <origin rpy="1.57079632679 0 0" xyz="0 0 0"/>
      <geometry>
        <cylinder length="0.15" radius="0.064"/>
      </geometry>
    </visual>
    <!-- <visual>
            <geometry>
                <box size="0.01 0.15 0.14"/>
            </geometry>
        </visual>
        <visual>
            <geometry>
                <box size="0.14 0.15 0.01"/>
            </geometry>
        </visual> -->
    <collision>
      <origin rpy="1.57079632679 0 0" xyz="0 0 0"/>
      <geometry>
        <cylinder length="0.1" radius="0.064"/>
      </geometry>
    </collision>
  </link>
  <joint name="left_sprocket_axle" type="fixed">
    <origin rpy="0 0 0" xyz="0.36 0.000287 -0.018"/>
    <parent link="left_body"/>
    <child link="left_sprocket"/>
    <axis xyz="0 1 0"/>
  </joint>
  <!-- <transmission name="${prefix}_sprocket_transmission">
        <type>transmission_interface/SimpleTransmission</type>
        <joint name="${prefix}_sprocket_axle">
            <hardwareInterface>hardware_interface/VelocityJointInterface</hardwareInterface>
        </joint>
        <actuator name="${prefix}_sprocket_actuator">
            <mechanicalReduction>1</mechanicalReduction>
        </actuator>
    </transmission>  -->
  <link name="right_body">
    <inertial>
      <mass value="1"/>
      <inertia ixx="0.0250083333333" ixy="0" ixz="0" iyy="0.0241666666667" iyz="0" izz="0.0425083333333"/>
    </inertial>
    <visual>
      <geometry>
        <!-- <box size="0.4 0.151 0.15"/> -->
        <mesh filename="package://mm_description/meshes/vehicle/track_entity_meter.STL"/>
      </geometry>
    </visual>
    <collision>
      <geometry>
        <box size="0.4 0.151 0.15"/>
      </geometry>
    </collision>
  </link>
  <gazebo reference="right_body">
    <material>Gazebo/DarkGrey</material>
  </gazebo>
  <gazebo reference="right_body_fixed_idler_link_1">
    <material>Gazebo/DarkGrey</material>
  </gazebo>
  <gazebo reference="right_body_fixed_idler_link_2">
    <material>Gazebo/DarkGrey</material>
  </gazebo>
  <gazebo reference="right_body_fixed_idler_link_3">
    <material>Gazebo/DarkGrey</material>
  </gazebo>
  <gazebo reference="right_sprocket">
    <material>Gazebo/DarkGrey</material>
  </gazebo>
  <!-- body cylinder: back-->
  <link name="right_body_fixed_idler_link_1">
    <inertial>
      <mass value="0.2"/>
      <inertia ixx="0.004655" ixy="0" ixz="0" iyy="0.00064" iyz="0" izz="0.004655"/>
    </inertial>
    <visual>
      <origin rpy="1.57079632679 0 0" xyz="0 0 0"/>
      <geometry>
        <cylinder length="0.15" radius="0.08"/>
      </geometry>
    </visual>
    <collision>
      <origin rpy="1.57079632679 0 0" xyz="0 0 0"/>
      <geometry>
        <cylinder length="0.15" radius="0.08"/>
      </geometry>
    </collision>
  </link>
  <joint name="right_body_fixed_idler_joint_1" type="fixed">
    <origin rpy="0 0 0" xyz="-0.36 0 0"/>
    <parent link="right_body"/>
    <child link="right_body_fixed_idler_link_1"/>
  </joint>
  <!-- body cylinder: front-->
  <link name="right_body_fixed_idler_link_2">
    <inertial>
      <mass value="0.2"/>
      <inertia ixx="0.004655" ixy="0" ixz="0" iyy="0.00064" iyz="0" izz="0.004655"/>
    </inertial>
    <visual>
      <origin rpy="1.57079632679 0 0" xyz="0 0 0"/>
      <geometry>
        <cylinder length="0.15" radius="0.07"/>
      </geometry>
    </visual>
    <collision>
      <origin rpy="1.57079632679 0 0" xyz="0 0 0"/>
      <geometry>
        <cylinder length="0.15" radius="0.07"/>
      </geometry>
    </collision>
  </link>
  <joint name="right_body_fixed_idler_joint_2" type="fixed">
    <origin rpy="0 0 0" xyz="0.445 0 0.102"/>
    <parent link="right_body"/>
    <child link="right_body_fixed_idler_link_2"/>
  </joint>
  <!-- body cylinder: top-->
  <link name="right_body_fixed_idler_link_3">
    <inertial>
      <mass value="0.2"/>
      <inertia ixx="0.004655" ixy="0" ixz="0" iyy="0.00064" iyz="0" izz="0.004655"/>
    </inertial>
    <visual>
      <origin rpy="1.57079632679 0 0" xyz="0 0 0"/>
      <geometry>
        <cylinder length="0.15" radius="0.062"/>
      </geometry>
    </visual>
    <collision>
      <origin rpy="1.57079632679 0 0" xyz="0 0 0"/>
      <geometry>
        <cylinder length="0.15" radius="0.062"/>
      </geometry>
    </collision>
  </link>
  <joint name="right_body_fixed_idler_joint_3" type="fixed">
    <origin rpy="0 0 0" xyz="0.00953 0 0.16618"/>
    <parent link="right_body"/>
    <child link="right_body_fixed_idler_link_3"/>
  </joint>
  <!-- sprocket driving the track : cylinder -->
  <link name="right_sprocket">
    <inertial>
      <mass value="0.2"/>
      <!-- assuming axis of cylinder is y, not z -->
      <inertia ixx="0.004655" ixy="0" ixz="0" iyy="0.00064" iyz="0" izz="0.004655"/>
    </inertial>
    <visual>
      <origin rpy="1.57079632679 0 0" xyz="0 0 0"/>
      <geometry>
        <cylinder length="0.15" radius="0.064"/>
      </geometry>
    </visual>
    <!-- <visual>
            <geometry>
                <box size="0.01 0.15 0.14"/>
            </geometry>
        </visual>
        <visual>
            <geometry>
                <box size="0.14 0.15 0.01"/>
            </geometry>
        </visual> -->
    <collision>
      <origin rpy="1.57079632679 0 0" xyz="0 0 0"/>
      <geometry>
        <cylinder length="0.1" radius="0.064"/>
      </geometry>
    </collision>
  </link>
  <joint name="right_sprocket_axle" type="fixed">
    <origin rpy="0 0 0" xyz="0.36 -0.000287 -0.018"/>
    <parent link="right_body"/>
    <child link="right_sprocket"/>
    <axis xyz="0 1 0"/>
  </joint>
  <!-- <transmission name="${prefix}_sprocket_transmission">
        <type>transmission_interface/SimpleTransmission</type>
        <joint name="${prefix}_sprocket_axle">
            <hardwareInterface>hardware_interface/VelocityJointInterface</hardwareInterface>
        </joint>
        <actuator name="${prefix}_sprocket_actuator">
            <mechanicalReduction>1</mechanicalReduction>
        </actuator>
    </transmission>  -->
  <link name="arm_body">
    <inertial>
      <mass value="0.3"/>
      <inertia ixx="0.0250083333333" ixy="0" ixz="0" iyy="0.0241666666667" iyz="0" izz="0.0425083333333"/>
    </inertial>
    <visual>
      <geometry>
        <box size="0.375 0.18 0.11"/>
      </geometry>
    </visual>
    <collision>
      <geometry>
        <box size="0.375 0.18 0.11"/>
      </geometry>
    </collision>
  </link>
  <link name="arm_connector">
    <inertial>
      <mass value="0.2"/>
      <!-- assuming axis of cylinder is y, not z -->
      <inertia ixx="0.004655" ixy="0" ixz="0" iyy="0.00064" iyz="0" izz="0.004655"/>
    </inertial>
    <visual>
      <origin rpy="1.57079632679 0 0" xyz="0 0 0"/>
      <geometry>
        <cylinder length="0.25" radius="0.035"/>
      </geometry>
    </visual>
    <collision>
      <origin rpy="1.57079632679 0 0" xyz="0 0 0"/>
      <geometry>
        <cylinder length="0.25" radius="0.035"/>
      </geometry>
    </collision>
  </link>
  <joint name="arm_connector_joint" type="fixed">
    <origin rpy="0 0 0" xyz="-0.188 0 0"/>
    <parent link="arm_connector"/>
    <child link="arm_body"/>
    <axis xyz="0 1 0"/>
  </joint>
  <!-- sprocket driving the track : cylinder -->
  <link name="sprocket">
    <inertial>
      <mass value="0.2"/>
      <!-- assuming axis of cylinder is y, not z -->
      <inertia ixx="0.004655" ixy="0" ixz="0" iyy="0.00064" iyz="0" izz="0.004655"/>
    </inertial>
    <visual>
      <origin rpy="1.57079632679 0 0" xyz="0 0 0"/>
      <geometry>
        <cylinder length="0.18" radius="0.055"/>
      </geometry>
    </visual>
    <collision>
      <origin rpy="1.57079632679 0 0" xyz="0 0 0"/>
      <geometry>
        <cylinder length="0.18" radius="0.055"/>
      </geometry>
    </collision>
  </link>
  <joint name="sprocket_axle" type="fixed">
    <origin rpy="0 0 0" xyz="0.188 0 0"/>
    <parent link="arm_body"/>
    <child link="sprocket"/>
    <axis xyz="0 1 0"/>
  </joint>
  <!-- <transmission name="arm_sprocket_transmission">
        <type>transmission_interface/SimpleTransmission</type>
        <joint name="sprocket_axle">
            <hardwareInterface>hardware_interface/VelocityJointInterface</hardwareInterface>
        </joint>
        <actuator name="sprocket_actuator">
            <mechanicalReduction>1</mechanicalReduction>
        </actuator>
    </transmission> -->
  <!-- idler on the other side of the sprocket: cylinder -->
  <link name="idler">
    <inertial>
      <mass value="0.2"/>
      <!-- assuming axis of cylinder is y, not z -->
      <inertia ixx="0.004655" ixy="0" ixz="0" iyy="0.00064" iyz="0" izz="0.004655"/>
    </inertial>
    <visual>
      <origin rpy="1.57079632679 0 0" xyz="0 0 0"/>
      <geometry>
        <cylinder length="0.18" radius="0.055"/>
      </geometry>
    </visual>
    <collision>
      <origin rpy="1.57079632679 0 0" xyz="0 0 0"/>
      <geometry>
        <cylinder length="0.18" radius="0.055"/>
      </geometry>
    </collision>
  </link>
  <joint name="idler_axle" type="fixed">
    <origin rpy="0 0 0" xyz="-0.188 0 0"/>
    <parent link="arm_body"/>
    <child link="idler"/>
  </joint>
  <gazebo reference="arm_body">
    <material>Gazebo/DarkGrey</material>
  </gazebo>
  <gazebo reference="arm_connector">
    <material>Gazebo/DarkGrey</material>
  </gazebo>
  <gazebo reference="sprocket">
    <material>Gazebo/DarkGrey</material>
  </gazebo>
  <gazebo reference="idler">
    <material>Gazebo/DarkGrey</material>
  </gazebo>
  <gazebo reference="vehicle_base_link">
    <material>Gazebo/DarkGrey</material>
  </gazebo>
  <gazebo reference="pusher_visual_left">
    <material>Gazebo/DarkGrey</material>
  </gazebo>
  <gazebo reference="pusher_visual_right">
    <material>Gazebo/DarkGrey</material>
  </gazebo>
  <link name="vehicle_base_link">
    <inertial>
      <mass value="50"/>
      <inertia ixx="5.250416666666667" ixy="0" ixz="0" iyy="5.208333333333333" iyz="0" izz="2.1254166666666667"/>
    </inertial>
    <visual>
      <geometry>
        <!-- <box size="0.4 0.4 0.1" /> -->
        <mesh filename="package://mm_description/meshes/vehicle/base_meter.STL"/>
      </geometry>
    </visual>
    <collision>
      <geometry>
        <box size="0.4 0.4 0.1"/>
        <!-- <mesh filename="package://mm_description/meshes/vehicle/base_meter.STL" /> -->
      </geometry>
    </collision>
  </link>
  <joint name="left_track_joint" type="fixed">
    <origin rpy="0 0 0" xyz="0 0.287 0"/>
    <parent link="vehicle_base_link"/>
    <child link="left_body"/>
  </joint>
  <joint name="right_track_joint" type="fixed">
    <origin rpy="0 0 0" xyz="0 -0.287 0"/>
    <parent link="vehicle_base_link"/>
    <child link="right_body"/>
  </joint>
  <link name="pusher_visual_left">
    <inertial>
      <mass value="1"/>
      <inertia ixx="0.10500833333333333" ixy="0" ixz="0" iyy="0.10416666666666667" iyz="0" izz="0.042508333333333335"/>
    </inertial>
    <visual>
      <geometry>
        <box size="0.5 0.025  0.08"/>
      </geometry>
    </visual>
    <collision>
      <geometry>
        <box size="0.5 0.025  0.08"/>
      </geometry>
    </collision>
  </link>
  <link name="pusher_visual_right">
    <inertial>
      <mass value="1"/>
      <inertia ixx="0.10500833333333333" ixy="0" ixz="0" iyy="0.10416666666666667" iyz="0" izz="0.042508333333333335"/>
    </inertial>
    <visual>
      <geometry>
        <box size="0.5 0.025  0.08"/>
      </geometry>
    </visual>
    <collision>
      <geometry>
        <box size="0.5 0.025 0.08"/>
      </geometry>
    </collision>
  </link>
  <joint name="pusher_visual_left_joint" type="fixed">
    <origin rpy="0 0 0" xyz="-0.27 0.12 0"/>
    <parent link="vehicle_base_link"/>
    <child link="pusher_visual_left"/>
  </joint>
  <joint name="pusher_visual_right_joint" type="fixed">
    <origin rpy="0 0 0" xyz="-0.27 -0.12 0"/>
    <parent link="vehicle_base_link"/>
    <child link="pusher_visual_right"/>
  </joint>
  <!-- Defining the colors used in this robot -->
  <material name="yellow">
    <color rgba="1 0.4 0 1"/>
  </material>
  <material name="black">
    <color rgba="0 0 0 0.95"/>
  </material>
  <material name="gray">
    <color rgba="0.75 0.75 0.75 1"/>
  </material>
  <link name="left_wheel_link">
    <collision>
      <origin rpy="1.5707963 0 0" xyz="0 0 0"/>
      <geometry>
        <cylinder length="0.07" radius="0.15"/>
      </geometry>
    </collision>
    <cylinder_inertial_matrix h="0.07" m="1" r="0.15"/>
  </link>
  <joint name="left_wheel_joint" type="continuous">
    <parent link="vehicle_base_link"/>
    <child link="left_wheel_link"/>
    <origin rpy="0 0 0" xyz="0 0.287 0.05999999999999999"/>
    <axis xyz="0 1 0"/>
  </joint>
  <gazebo reference="left_wheel_link">
    <material>Gazebo/Gray</material>
  </gazebo>
  <gazebo reference="left_wheel_link">
    <mu1 value="1000"/>
    <mu2 value="1000"/>
  </gazebo>
  <!-- Transmission is important to link the joints and the controller -->
  <transmission name="left_wheel_joint_trans">
    <type>transmission_interface/SimpleTransmission</type>
    <joint name="left_wheel_joint">
      <hardwareInterface>hardware_interface/VelocityJointInterface</hardwareInterface>
    </joint>
    <actuator name="left_wheel_motor">
      <hardwareInterface>hardware_interface/VelocityJointInterface</hardwareInterface>
      <mechanicalReduction>1</mechanicalReduction>
    </actuator>
  </transmission>
  <link name="right_wheel_link">
    <collision>
      <origin rpy="1.5707963 0 0" xyz="0 0 0"/>
      <geometry>
        <cylinder length="0.07" radius="0.15"/>
      </geometry>
    </collision>
    <cylinder_inertial_matrix h="0.07" m="1" r="0.15"/>
  </link>
  <joint name="right_wheel_joint" type="continuous">
    <parent link="vehicle_base_link"/>
    <child link="right_wheel_link"/>
    <origin rpy="0 0 0" xyz="0 -0.287 0.05999999999999999"/>
    <axis xyz="0 1 0"/>
  </joint>
  <gazebo reference="right_wheel_link">
    <material>Gazebo/Gray</material>
  </gazebo>
  <gazebo reference="right_wheel_link">
    <mu1 value="1000"/>
    <mu2 value="1000"/>
  </gazebo>
  <!-- Transmission is important to link the joints and the controller -->
  <transmission name="right_wheel_joint_trans">
    <type>transmission_interface/SimpleTransmission</type>
    <joint name="right_wheel_joint">
      <hardwareInterface>hardware_interface/VelocityJointInterface</hardwareInterface>
    </joint>
    <actuator name="right_wheel_motor">
      <hardwareInterface>hardware_interface/VelocityJointInterface</hardwareInterface>
      <mechanicalReduction>1</mechanicalReduction>
    </actuator>
  </transmission>
  <link name="front_left_caster_link">
    <collision>
      <origin rpy="0 0 0" xyz="0 0 0"/>
      <geometry>
        <sphere radius="0.05"/>
      </geometry>
    </collision>
    <sphere_inertial_matrix m="0.2" r="0.05"/>
  </link>
  <gazebo reference="front_left_caster_link">
    <material>Gazebo/Black</material>
  </gazebo>
  <gazebo reference="front_left_caster_link">
    <mu1 value="0"/>
    <mu2 value="0"/>
  </gazebo>
  <joint name="front_left_caster_joint" type="fixed">
    <origin rpy="0 0 0" xyz="0.45 0.287 -0.039999999999999994"/>
    <parent link="vehicle_base_link"/>
    <child link="front_left_caster_link"/>
  </joint>
  <link name="front_right_caster_link">
    <collision>
      <origin rpy="0 0 0" xyz="0 0 0"/>
      <geometry>
        <sphere radius="0.05"/>
      </geometry>
    </collision>
    <sphere_inertial_matrix m="0.2" r="0.05"/>
  </link>
  <gazebo reference="front_right_caster_link">
    <material>Gazebo/Black</material>
  </gazebo>
  <gazebo reference="front_right_caster_link">
    <mu1 value="0"/>
    <mu2 value="0"/>
  </gazebo>
  <joint name="front_right_caster_joint" type="fixed">
    <origin rpy="0 0 0" xyz="0.45 -0.287 -0.039999999999999994"/>
    <parent link="vehicle_base_link"/>
    <child link="front_right_caster_link"/>
  </joint>
  <link name="back_left_caster_link">
    <collision>
      <origin rpy="0 0 0" xyz="0 0 0"/>
      <geometry>
        <sphere radius="0.05"/>
      </geometry>
    </collision>
    <sphere_inertial_matrix m="0.2" r="0.05"/>
  </link>
  <gazebo reference="back_left_caster_link">
    <material>Gazebo/Black</material>
  </gazebo>
  <gazebo reference="back_left_caster_link">
    <mu1 value="0"/>
    <mu2 value="0"/>
  </gazebo>
  <joint name="back_left_caster_joint" type="fixed">
    <origin rpy="0 0 0" xyz="-0.45 0.287 -0.039999999999999994"/>
    <parent link="vehicle_base_link"/>
    <child link="back_left_caster_link"/>
  </joint>
  <link name="back_right_caster_link">
    <collision>
      <origin rpy="0 0 0" xyz="0 0 0"/>
      <geometry>
        <sphere radius="0.05"/>
      </geometry>
    </collision>
    <sphere_inertial_matrix m="0.2" r="0.05"/>
  </link>
  <gazebo reference="back_right_caster_link">
    <material>Gazebo/Black</material>
  </gazebo>
  <gazebo reference="back_right_caster_link">
    <mu1 value="0"/>
    <mu2 value="0"/>
  </gazebo>
  <joint name="back_right_caster_joint" type="fixed">
    <origin rpy="0 0 0" xyz="-0.45 -0.287 -0.039999999999999994"/>
    <parent link="vehicle_base_link"/>
    <child link="back_right_caster_link"/>
  </joint>
  <!-- <link name="push_plate">
        <xacro:make_box_inertia mass="1" size_x="0.5" size_y="0.51" size_z="1" />
        <visual>
            <geometry>
                <box size="0.1 0.2 0.03" />
            </geometry>
        </visual>

        <collision>
            <geometry>
                <box size="0.1 0.2 0.03" />
            </geometry>
        </collision>
    </link> -->
  <joint name="push_plate_joint" type="fixed">
    <origin rpy="0 1 0" xyz="-0.479 0 0"/>
    <parent link="vehicle_base_link"/>
    <child link="arm_connector"/>
    <axis xyz="0 1 0"/>
  </joint>
  <!-- <transmission name="push_plate_joint_transmission">
        <type>transmission_interface/SimpleTransmission</type>
        <joint name="push_plate_joint">
            <hardwareInterface>hardware_interface/EffortJointInterface</hardwareInterface>
        </joint>
        <actuator name="push_plate_joint_motor">
            <hardwareInterface>hardware_interface/EffortJointInterface</hardwareInterface>
            <mechanicalReduction>1</mechanicalReduction>
        </actuator>
    </transmission> -->
  <!-- ros_control for gazebo, should only load once!! -->
  <!-- <gazebo>
        <plugin filename="libgazebo_ros_control.so" name="gazebo_ros_control">
            <robotSimType>gazebo_ros_control/DefaultRobotHWSim</robotSimType>
            <legacyModeNS>true</legacyModeNS>
        </plugin>
    </gazebo> -->
  <joint name="base_footprint_joint" type="fixed">
    <origin rpy="0 0 0" xyz="0 0 0"/>
    <parent link="base_footprint"/>
    <child link="vehicle_base_link"/>
  </joint>
  <link name="board_link">
    <origin rpy="0 0 0" xyz="0.0 0.0 0.0"/>
    <visual>
      <geometry>
        <mesh filename="package://mm_description/meshes/vehicle/board_link.STL"/>
      </geometry>
    </visual>
    <collision>
      <geometry>
        <mesh filename="package://mm_description/meshes/vehicle/board_link.STL"/>
      </geometry>
    </collision>
  </link>
  <link name="support_link">
    <origin rpy="0 0 0" xyz="0.0 0.0 0.0"/>
    <visual>
      <geometry>
        <mesh filename="package://mm_description/meshes/vehicle/support_link.STL"/>
      </geometry>
    </visual>
    <collision>
      <geometry>
        <mesh filename="package://mm_description/meshes/vehicle/support_link.STL"/>
      </geometry>
    </collision>
  </link>
  <link name="lidar_support_link">
    <origin rpy="-3.14 0 0" xyz="0.0 0.0 0.0"/>
    <visual>
      <geometry>
        <mesh filename="package://mm_description/meshes/vehicle/lidar_support.STL"/>
      </geometry>
    </visual>
    <collision>
      <geometry>
        <mesh filename="package://mm_description/meshes/vehicle/lidar_support.STL"/>
      </geometry>
    </collision>
  </link>
  <joint name="lidar_support_joint" type="fixed">
    <origin rpy="0 0 0" xyz="0.14 0.0 0.68"/>
    <parent link="support_link"/>
    <child link="lidar_support_link"/>
  </joint>
  <joint name="board_joint" type="fixed">
    <origin rpy="0 0 0" xyz="-0.055 0 0.32"/>
    <parent link="vehicle_base_link"/>
    <child link="board_link"/>
  </joint>
  <joint name="support_joint" type="fixed">
    <origin rpy="0 0 0" xyz="-0.2 0.0 0.32"/>
    <parent link="vehicle_base_link"/>
    <child link="support_link"/>
  </joint>
  <!--property name="shoulder_height" value="0.089159" /-->
  <!--property name="shoulder_offset" value="0.13585" /-->
  <!-- shoulder_offset - elbow_offset + wrist_1_length = 0.10915 -->
  <!--property name="upper_arm_length" value="0.42500" /-->
  <!--property name="elbow_offset" value="0.1197" /-->
  <!-- CAD measured -->
  <!--property name="forearm_length" value="0.39225" /-->
  <!--property name="wrist_1_length" value="0.093" /-->
  <!-- CAD measured -->
  <!--property name="wrist_2_length" value="0.09465" /-->
  <!-- In CAD this distance is 0.930, but in the spec it is 0.09465 -->
  <!--property name="wrist_3_length" value="0.0823" /-->
  <!-- manually measured -->
  <link name="base_link">
    <visual>
      <geometry>
        <mesh filename="package://mm_description/meshes/ur5e/visual/base.dae"/>
      </geometry>
      <material name="LightGrey">
        <color rgba="0.7 0.7 0.7 1.0"/>
      </material>
    </visual>
    <collision>
      <geometry>
        <mesh filename="package://mm_description/meshes/ur5e/collision/base.stl"/>
      </geometry>
    </collision>
    <inertial>
      <mass value="4.0"/>
      <origin rpy="0 0 0" xyz="0.0 0.0 0.0"/>
      <inertia ixx="0.00443333156" ixy="0.0" ixz="0.0" iyy="0.00443333156" iyz="0.0" izz="0.0072"/>
    </inertial>
  </link>
  <joint name="shoulder_pan_joint" type="revolute">
    <parent link="base_link"/>
    <child link="shoulder_link"/>
    <origin rpy="0.0 0.0 0.0" xyz="0.0 0.0 0.163"/>
    <axis xyz="0 0 1"/>
    <limit effort="150.0" lower="-3.141592653589793" upper="3.141592653589793" velocity="3.14"/>
    <dynamics damping="0.0" friction="0.0"/>
  </joint>
  <link name="shoulder_link">
    <visual>
      <geometry>
        <mesh filename="package://mm_description/meshes/ur5e/visual/shoulder.dae"/>
      </geometry>
      <material name="LightGrey">
        <color rgba="0.7 0.7 0.7 1.0"/>
      </material>
    </visual>
    <collision>
      <geometry>
        <mesh filename="package://mm_description/meshes/ur5e/collision/shoulder.stl"/>
      </geometry>
    </collision>
    <inertial>
      <mass value="3.7"/>
      <origin rpy="0 0 0" xyz="0.0 0.0 0.0"/>
      <inertia ixx="0.010267495893" ixy="0.0" ixz="0.0" iyy="0.010267495893" iyz="0.0" izz="0.00666"/>
    </inertial>
  </link>
  <joint name="shoulder_lift_joint" type="revolute">
    <parent link="shoulder_link"/>
    <child link="upper_arm_link"/>
    <origin rpy="0.0 1.5707963267948966 0.0" xyz="0.0 0.138 0.0"/>
    <axis xyz="0 1 0"/>
    <limit effort="150.0" lower="-3.141592653589793" upper="3.141592653589793" velocity="3.14"/>
    <dynamics damping="0.0" friction="0.0"/>
  </joint>
  <link name="upper_arm_link">
    <visual>
      <geometry>
        <mesh filename="package://mm_description/meshes/ur5e/visual/upperarm.dae"/>
      </geometry>
      <material name="LightGrey">
        <color rgba="0.7 0.7 0.7 1.0"/>
      </material>
    </visual>
    <collision>
      <geometry>
        <mesh filename="package://mm_description/meshes/ur5e/collision/upperarm.stl"/>
      </geometry>
    </collision>
    <inertial>
      <mass value="8.393"/>
      <origin rpy="0 0 0" xyz="0.0 0.0 0.2125"/>
      <inertia ixx="0.1338857818623325" ixy="0.0" ixz="0.0" iyy="0.1338857818623325" iyz="0.0" izz="0.0151074"/>
    </inertial>
  </link>
  <joint name="elbow_joint" type="revolute">
    <parent link="upper_arm_link"/>
    <child link="forearm_link"/>
    <origin rpy="0.0 0.0 0.0" xyz="0.0 -0.131 0.425"/>
    <axis xyz="0 1 0"/>
    <limit effort="150.0" lower="-3.141592653589793" upper="3.141592653589793" velocity="3.14"/>
    <dynamics damping="0.0" friction="0.0"/>
  </joint>
  <link name="forearm_link">
    <visual>
      <geometry>
        <mesh filename="package://mm_description/meshes/ur5e/visual/forearm.dae"/>
      </geometry>
      <material name="LightGrey">
        <color rgba="0.7 0.7 0.7 1.0"/>
      </material>
    </visual>
    <collision>
      <geometry>
        <mesh filename="package://mm_description/meshes/ur5e/collision/forearm.stl"/>
      </geometry>
    </collision>
    <inertial>
      <mass value="2.275"/>
      <origin rpy="0 0 0" xyz="0.0 0.0 0.196"/>
      <inertia ixx="0.031179620861480004" ixy="0.0" ixz="0.0" iyy="0.031179620861480004" iyz="0.0" izz="0.004095"/>
    </inertial>
  </link>
  <joint name="wrist_1_joint" type="revolute">
    <parent link="forearm_link"/>
    <child link="wrist_1_link"/>
    <origin rpy="0.0 1.5707963267948966 0.0" xyz="0.0 0.0 0.392"/>
    <axis xyz="0 1 0"/>
    <limit effort="28.0" lower="-3.141592653589793" upper="3.141592653589793" velocity="6.28"/>
    <dynamics damping="0.0" friction="0.0"/>
  </joint>
  <link name="wrist_1_link">
    <visual>
      <geometry>
        <mesh filename="package://mm_description/meshes/ur5e/visual/wrist1.dae"/>
      </geometry>
      <material name="LightGrey">
        <color rgba="0.7 0.7 0.7 1.0"/>
      </material>
    </visual>
    <collision>
      <geometry>
        <mesh filename="package://mm_description/meshes/ur5e/collision/wrist1.stl"/>
      </geometry>
    </collision>
    <inertial>
      <mass value="1.219"/>
      <origin rpy="0 0 0" xyz="0.0 0.127 0.0"/>
      <inertia ixx="0.0025598989760400002" ixy="0.0" ixz="0.0" iyy="0.0025598989760400002" iyz="0.0" izz="0.0021942"/>
    </inertial>
  </link>
  <joint name="wrist_2_joint" type="revolute">
    <parent link="wrist_1_link"/>
    <child link="wrist_2_link"/>
    <origin rpy="0.0 0.0 0.0" xyz="0.0 0.127 0.0"/>
    <axis xyz="0 0 1"/>
    <limit effort="28.0" lower="-3.141592653589793" upper="3.141592653589793" velocity="6.28"/>
    <dynamics damping="0.0" friction="0.0"/>
  </joint>
  <link name="wrist_2_link">
    <visual>
      <geometry>
        <mesh filename="package://mm_description/meshes/ur5e/visual/wrist2.dae"/>
      </geometry>
      <material name="LightGrey">
        <color rgba="0.7 0.7 0.7 1.0"/>
      </material>
    </visual>
    <collision>
      <geometry>
        <mesh filename="package://mm_description/meshes/ur5e/collision/wrist2.stl"/>
      </geometry>
    </collision>
    <inertial>
      <mass value="1.219"/>
      <origin rpy="0 0 0" xyz="0.0 0.0 0.1"/>
      <inertia ixx="0.0025598989760400002" ixy="0.0" ixz="0.0" iyy="0.0025598989760400002" iyz="0.0" izz="0.0021942"/>
    </inertial>
  </link>
  <joint name="wrist_3_joint" type="revolute">
    <parent link="wrist_2_link"/>
    <child link="wrist_3_link"/>
    <origin rpy="0.0 0.0 0.0" xyz="0.0 0.0 0.1"/>
    <axis xyz="0 1 0"/>
    <limit effort="28.0" lower="-3.141592653589793" upper="3.141592653589793" velocity="6.28"/>
    <dynamics damping="0.0" friction="0.0"/>
  </joint>
  <link name="wrist_3_link">
    <visual>
      <geometry>
        <mesh filename="package://mm_description/meshes/ur5e/visual/wrist3.dae"/>
      </geometry>
      <material name="LightGrey">
        <color rgba="0.7 0.7 0.7 1.0"/>
      </material>
    </visual>
    <collision>
      <geometry>
        <mesh filename="package://mm_description/meshes/ur5e/collision/wrist3.stl"/>
      </geometry>
    </collision>
    <inertial>
      <mass value="0.1879"/>
      <origin rpy="1.5707963267948966 0 0" xyz="0.0 0.0771 0.0"/>
      <inertia ixx="9.890410052167731e-05" ixy="0.0" ixz="0.0" iyy="9.890410052167731e-05" iyz="0.0" izz="0.0001321171875"/>
    </inertial>
  </link>
  <joint name="ee_fixed_joint" type="fixed">
    <parent link="wrist_3_link"/>
    <child link="ee_link"/>
    <origin rpy="0.0 0.0 1.5707963267948966" xyz="0.0 0.1 0.0"/>
  </joint>
  <link name="ee_link">
    <collision>
      <geometry>
        <box size="0.01 0.01 0.01"/>
      </geometry>
      <origin rpy="0 0 0" xyz="-0.01 0 0"/>
    </collision>
  </link>
  <transmission name="shoulder_pan_trans">
    <type>transmission_interface/SimpleTransmission</type>
    <joint name="shoulder_pan_joint">
      <hardwareInterface>hardware_interface/PositionJointInterface</hardwareInterface>
    </joint>
    <actuator name="shoulder_pan_motor">
      <mechanicalReduction>1</mechanicalReduction>
    </actuator>
  </transmission>
  <transmission name="shoulder_lift_trans">
    <type>transmission_interface/SimpleTransmission</type>
    <joint name="shoulder_lift_joint">
      <hardwareInterface>hardware_interface/PositionJointInterface</hardwareInterface>
    </joint>
    <actuator name="shoulder_lift_motor">
      <mechanicalReduction>1</mechanicalReduction>
    </actuator>
  </transmission>
  <transmission name="elbow_trans">
    <type>transmission_interface/SimpleTransmission</type>
    <joint name="elbow_joint">
      <hardwareInterface>hardware_interface/PositionJointInterface</hardwareInterface>
    </joint>
    <actuator name="elbow_motor">
      <mechanicalReduction>1</mechanicalReduction>
    </actuator>
  </transmission>
  <transmission name="wrist_1_trans">
    <type>transmission_interface/SimpleTransmission</type>
    <joint name="wrist_1_joint">
      <hardwareInterface>hardware_interface/PositionJointInterface</hardwareInterface>
    </joint>
    <actuator name="wrist_1_motor">
      <mechanicalReduction>1</mechanicalReduction>
    </actuator>
  </transmission>
  <transmission name="wrist_2_trans">
    <type>transmission_interface/SimpleTransmission</type>
    <joint name="wrist_2_joint">
      <hardwareInterface>hardware_interface/PositionJointInterface</hardwareInterface>
    </joint>
    <actuator name="wrist_2_motor">
      <mechanicalReduction>1</mechanicalReduction>
    </actuator>
  </transmission>
  <transmission name="wrist_3_trans">
    <type>transmission_interface/SimpleTransmission</type>
    <joint name="wrist_3_joint">
      <hardwareInterface>hardware_interface/PositionJointInterface</hardwareInterface>
    </joint>
    <actuator name="wrist_3_motor">
      <mechanicalReduction>1</mechanicalReduction>
    </actuator>
  </transmission>
  <gazebo reference="shoulder_link">
    <selfCollide>true</selfCollide>
  </gazebo>
  <gazebo reference="upper_arm_link">
    <selfCollide>true</selfCollide>
  </gazebo>
  <gazebo reference="forearm_link">
    <selfCollide>true</selfCollide>
  </gazebo>
  <gazebo reference="wrist_1_link">
    <selfCollide>true</selfCollide>
  </gazebo>
  <gazebo reference="wrist_3_link">
    <selfCollide>true</selfCollide>
  </gazebo>
  <gazebo reference="wrist_2_link">
    <selfCollide>true</selfCollide>
  </gazebo>
  <gazebo reference="ee_link">
    <selfCollide>true</selfCollide>
  </gazebo>
  <!-- 
    <gazebo reference="${prefix}ee_link">
      <pose>0 0 0 0 0 0</pose>
      <sensor name="${prefix}ee_link_force_torque" type="force_torque">
        <always_on>true</always_on>
        <update_rate>20.0</update_rate>
        <visualize>true</visualize>
        <force_torque>
          <frame>sensor</frame>
          <measure_direction>child_to_parent</measure_direction>
        </force_torque>
      </sensor>
    </gazebo> -->
  <joint name="associate_joint" type="fixed">
    <origin rpy="0 0 0" xyz="0.365 0 0.28"/>
    <parent link="vehicle_base_link"/>
    <child link="base_link"/>
  </joint>
  <!-- camera body, with origin at bottom screw mount -->
  <joint name="camera_joint" type="fixed">
    <origin rpy="1.5708 0 1.5708" xyz="0 -0.045 0.022"/>
    <parent link="ee_link"/>
    <child link="camera_flange_link"/>
  </joint>
  <link name="camera_flange_link">
    <visual>
      <geometry>
        <mesh filename="package://mm_description/meshes/d435/camera_flange_link.STL" scale="0.001 0.001 0.001"/>
      </geometry>
      <material name="LightGrey">
        <color rgba="0.75294 0.75294 0.75294 1"/>
      </material>
    </visual>
    <collision>
      <geometry>
        <mesh filename="package://mm_description/meshes/d435/camera_flange_link.STL" scale="0.001 0.001 0.001"/>
      </geometry>
    </collision>
    <inertial>
      <mass value="0.034"/>
      <origin xyz="0.0 0.0 0.0"/>
      <inertia ixx="0.0022573" ixy="0.000000" ixz="0.000000" iyx="0.000000" iyy="0.0038711" iyz="0.0003245" izx="0.000000" izy="0.0003245" izz="0.0023745"/>
    </inertial>
  </link>
  <joint name="camera_flange_link_joint" type="fixed">
    <origin rpy="0 0 0" xyz="0.04525 0.0455 0.09055"/>
    <parent link="camera_flange_link"/>
    <child link="camera_link"/>
  </joint>
  <link name="camera_link">
    <visual>
      <origin rpy="0 0 0" xyz="0 0 0"/>
      <geometry>
        <mesh filename="package://mm_description/meshes/d435/d435.dae"/>
      </geometry>
      <material name="aluminum">
        <color rgba="0.5 0.5 0.5 1"/>
      </material>
    </visual>
    <collision>
      <origin rpy="0 0 0" xyz="0 0 0"/>
      <geometry>
        <mesh filename="package://mm_description/meshes/d435/d435.dae"/>
      </geometry>
    </collision>
    <inertial>
      <!-- The following are not reliable values, and should not be used for modeling -->
      <mass value="0.564"/>
      <origin xyz="0 0 0"/>
      <inertia ixx="0.003881243" ixy="0.0" ixz="0.0" iyy="0.000498940" iyz="0.0" izz="0.003879257"/>
    </inertial>
  </link>
  <!-- camera depth joints and links -->
  <joint name="camera_depth_joint" type="fixed">
    <origin rpy="-1.5707963267948966 -1.5707963267948966 0" xyz="0 0 0"/>
    <parent link="camera_link"/>
    <child link="camera_depth_frame"/>
  </joint>
  <link name="camera_depth_frame"/>
  <!-- The default position is change since in Rviz the cloud depth axis is Z not X-->
  <joint name="camera_depth_optical_joint" type="fixed">
    <origin rpy="1.5707963267948966 3.141592653589793 1.5707963267948966" xyz="0 0 0"/>
    <parent link="camera_depth_frame"/>
    <child link="depth"/>
  </joint>
  <link name="depth"/>
  <!-- camera left IR joints and links -->
  <joint name="camera_infra1_joint" type="fixed">
    <origin rpy="-1.5707963267948966 -1.5707963267948966 0" xyz="-0.0325 0.0 0.0"/>
    <parent link="camera_link"/>
    <child link="camera_infra1_frame"/>
  </joint>
  <link name="camera_infra1_frame"/>
  <joint name="camera_infra1_optical_joint" type="fixed">
    <origin rpy="0 0 0" xyz="0 0 0"/>
    <parent link="camera_infra1_frame"/>
    <child link="ired1"/>
  </joint>
  <link name="ired1"/>
  <!-- camera right IR joints and links -->
  <joint name="camera_infra2_joint" type="fixed">
    <origin rpy="-1.5707963267948966 -1.5707963267948966 0" xyz="0.0175 0.0 0.0"/>
    <parent link="camera_link"/>
    <child link="camera_infra2_frame"/>
  </joint>
  <link name="camera_infra2_frame"/>
  <joint name="camera_infra2_optical_joint" type="fixed">
    <origin rpy="0 0 0" xyz="0 0 0"/>
    <parent link="camera_infra2_frame"/>
    <child link="ired2"/>
  </joint>
  <link name="ired2"/>
  <!-- camera color joints and links -->
  <joint name="camera_color_joint" type="fixed">
    <origin rpy="-1.5707963267948966 -1.5707963267948966 0" xyz="0.0325 0.0 0.0"/>
    <parent link="camera_link"/>
    <child link="camera_color_frame"/>
  </joint>
  <link name="camera_color_frame"/>
  <joint name="camera_color_optical_joint" type="fixed">
    <origin rpy="0 0 0" xyz="0 0 0"/>
    <parent link="camera_color_frame"/>
    <child link="color"/>
  </joint>
  <link name="color"/>
  <!-- sensor name (color/ired1/ired2/depth) is defined in realsense gazebo plugin, do not change. -->
  <gazebo>
    <plugin filename="librealsense_gazebo_plugin.so" name="d435">
      <depthUpdateRate>30</depthUpdateRate>
      <colorUpdateRate>30</colorUpdateRate>
      <infraredUpdateRate>30</infraredUpdateRate>
      <depthTopicName>camera/depth/image_raw</depthTopicName>
      <depthCameraInfoTopicName>depth_camera</depthCameraInfoTopicName>
      <!-- Not used -->
      <colorTopicName>camera/color/image_raw</colorTopicName>
      <colorCameraInfoTopicName>color_camera</colorCameraInfoTopicName>
      <!-- Not used -->
      <infrared1TopicName>camera/ir/image_raw</infrared1TopicName>
      <infrared1CameraInfoTopicName>ir_camera</infrared1CameraInfoTopicName>
      <!-- Not used -->
      <infrared2TopicName>camera/ir2/image_raw</infrared2TopicName>
      <infrared2CameraInfoTopicName>ir2_camera</infrared2CameraInfoTopicName>
      <!-- Not used -->
      <colorOpticalframeName>color</colorOpticalframeName>
      <!-- Same as sensor name -->
      <depthOpticalframeName>depth</depthOpticalframeName>
      <!-- Same as sensor name -->
      <infrared1OpticalframeName>ired1</infrared1OpticalframeName>
      <!-- Same as sensor name -->
      <infrared2OpticalframeName>ired2</infrared2OpticalframeName>
      <!-- Same as sensor name -->
      <rangeMinDepth>0.3</rangeMinDepth>
      <rangeMaxDepth>3.5.0</rangeMaxDepth>
      <!-- actually 10m used for mapping -->
      <pointCloud>1</pointCloud>
      <!-- enable pointCloud -->
      <pointCloudTopicName>camera/depth_registered/points</pointCloudTopicName>
      <pointCloudCutoff>0.3</pointCloudCutoff>
      <pointCloudCutoffMax>3.5.0</pointCloudCutoffMax>
    </plugin>
  </gazebo>
  <gazebo reference="camera_flange_link">
    <selfCollide>1</selfCollide>
  </gazebo>
  <gazebo reference="camera_link">
    <selfCollide>1</selfCollide>
  </gazebo>
  <gazebo reference="camera_color_frame">
    <selfCollide>1</selfCollide>
    <enable_wind>0</enable_wind>
    <kinematic>0</kinematic>
    <!-- <gravity>1</gravity> -->
    <!-- <mu>1</mu> -->
    <mu2>1</mu2>
    <fdir1>0 0 0</fdir1>
    <!-- <slip1>0</slip1>
      <slip2>0</slip2> -->
    <kp>1e+13</kp>
    <kd>1</kd>
    <!-- <max_vel>0.01</max_vel>
      <min_depth>0</min_depth> -->
    <sensor name="color" type="camera">
      <pose frame="">0 0 0 0 0 0</pose>
      <camera name="color_optical_frame">
        <horizontal_fov>1.047</horizontal_fov>
        <image>
          <width>640</width>
          <height>480</height>
          <format>RGB_INT8</format>
        </image>
        <clip>
          <near>0.1</near>
          <far>100</far>
        </clip>
        <noise>
          <type>gaussian</type>
          <mean>0.0</mean>
          <stddev>0.007</stddev>
        </noise>
      </camera>
      <always_on>1</always_on>
      <update_rate>60</update_rate>
      <visualize>1</visualize>
    </sensor>
  </gazebo>
  <gazebo reference="camera_infra1_frame">
    <selfCollide>1</selfCollide>
    <enable_wind>0</enable_wind>
    <kinematic>0</kinematic>
    <!-- <gravity>1</gravity> -->
    <!-- <mu>1</mu> -->
    <mu2>1</mu2>
    <fdir1>0 0 0</fdir1>
    <!-- <slip1>0</slip1>
      <slip2>0</slip2> -->
    <kp>1e+13</kp>
    <kd>1</kd>
    <!-- <max_vel>0.01</max_vel>
      <min_depth>0</min_depth> -->
    <sensor name="ired1" type="camera">
      <camera name="infra1_optical_frame">
        <horizontal_fov>1.047</horizontal_fov>
        <image>
          <width>640</width>
          <height>480</height>
          <format>L_INT8</format>
        </image>
        <clip>
          <near>0.1</near>
          <far>100</far>
        </clip>
        <noise>
          <type>gaussian</type>
          <mean>0.0</mean>
          <stddev>0.05</stddev>
        </noise>
      </camera>
      <always_on>1</always_on>
      <update_rate>60</update_rate>
      <visualize>0</visualize>
    </sensor>
  </gazebo>
  <gazebo reference="camera_infra2_frame">
    <selfCollide>1</selfCollide>
    <enable_wind>0</enable_wind>
    <kinematic>0</kinematic>
    <!-- <gravity>1</gravity> -->
    <!-- <mu>1</mu> -->
    <mu2>1</mu2>
    <fdir1>0 0 0</fdir1>
    <!-- <slip1>0</slip1>
      <slip2>0</slip2> -->
    <kp>1e+13</kp>
    <kd>1</kd>
    <!-- <max_vel>0.01</max_vel>
      <min_depth>0</min_depth> -->
    <sensor name="ired2" type="camera">
      <camera name="infra2_optical_frame">
        <horizontal_fov>1.047</horizontal_fov>
        <image>
          <width>640</width>
          <height>480</height>
          <format>L_INT8</format>
        </image>
        <clip>
          <near>0.1</near>
          <far>100</far>
        </clip>
        <noise>
          <type>gaussian</type>
          <mean>0.0</mean>
          <stddev>0.05</stddev>
        </noise>
      </camera>
      <always_on>1</always_on>
      <update_rate>60</update_rate>
      <visualize>0</visualize>
    </sensor>
  </gazebo>
  <gazebo reference="camera_depth_frame">
    <selfCollide>1</selfCollide>
    <enable_wind>0</enable_wind>
    <kinematic>0</kinematic>
    <!-- <gravity>1</gravity> -->
    <!-- <mu>1</mu> -->
    <mu2>1</mu2>
    <fdir1>0 0 0</fdir1>
    <!-- <slip1>0</slip1>
      <slip2>0</slip2> -->
    <kp>1e+13</kp>
    <kd>1</kd>
    <!-- <max_vel>0.01</max_vel>
      <min_depth>0</min_depth> -->
    <sensor name="depth" type="depth">
      <camera name="depth_optical_frame">
        <horizontal_fov>1.047</horizontal_fov>
        <image>
          <width>640</width>
          <height>480</height>
        </image>
        <clip>
          <near>0.1</near>
          <far>100</far>
        </clip>
        <noise>
          <type>gaussian</type>
          <mean>0.0</mean>
          <stddev>0.100</stddev>
        </noise>
      </camera>
      <always_on>1</always_on>
      <update_rate>60</update_rate>
      <visualize>0</visualize>
    </sensor>
  </gazebo>
  <!-- usb camera -->
  <!-- <xacro:include filename="$(find mm_description)/urdf/sensors/camera.xacro" />
    <xacro:usb_camera prefix="usb_camera" />
    <joint name="camera_support_joint" type="fixed">
        <origin xyz="0.30  0  0.50" rpy="0 0 0" />
        <parent link="support_link" />
        <child link="usb_camera_link" />
    </joint> -->
  <joint name="velodyne_base_mount_joint" type="fixed">
    <origin rpy="0 0 0" xyz="0.0 0.0 0.0"/>
    <parent link="lidar_support_link"/>
    <child link="velodyne_base_link"/>
  </joint>
  <link name="velodyne_base_link">
    <inertial>
      <mass value="0.83"/>
      <origin xyz="0 0 0.03585"/>
      <inertia ixx="0.000908059425" ixy="0" ixz="0" iyy="0.000908059425" iyz="0" izz="0.0011049624"/>
    </inertial>
    <visual>
      <geometry>
        <mesh filename="package://velodyne_description/meshes/VLP16_base_1.dae"/>
      </geometry>
    </visual>
    <visual>
      <geometry>
        <mesh filename="package://velodyne_description/meshes/VLP16_base_2.dae"/>
      </geometry>
    </visual>
    <collision>
      <origin rpy="0 0 0" xyz="0 0 0.03585"/>
      <geometry>
        <cylinder length="0.0717" radius="0.0516"/>
      </geometry>
    </collision>
  </link>
  <joint name="velodyne_base_scan_joint" type="fixed">
    <origin rpy="0 0 0" xyz="0 0 0.0377"/>
    <parent link="velodyne_base_link"/>
    <child link="velodyne"/>
  </joint>
  <link name="velodyne">
    <inertial>
      <mass value="0.01"/>
      <origin xyz="0 0 0"/>
      <inertia ixx="1e-7" ixy="0" ixz="0" iyy="1e-7" iyz="0" izz="1e-7"/>
    </inertial>
    <visual>
      <origin xyz="0 0 -0.0377"/>
      <geometry>
        <mesh filename="package://velodyne_description/meshes/VLP16_scan.dae"/>
      </geometry>
    </visual>
  </link>
  <!-- Gazebo requires the velodyne_gazebo_plugins package -->
  <gazebo reference="velodyne">
    <sensor name="velodyne-VLP16" type="gpu_ray">
      <pose>0 0 0 0 0 0</pose>
      <visualize>false</visualize>
      <update_rate>10</update_rate>
      <ray>
        <scan>
          <horizontal>
            <samples>1800</samples>
            <resolution>1</resolution>
            <min_angle>-3.141592653589793</min_angle>
            <max_angle>3.141592653589793</max_angle>
          </horizontal>
          <vertical>
            <samples>16</samples>
            <resolution>1</resolution>
            <min_angle>-0.2617993877991494</min_angle>
            <max_angle> 0.2617993877991494</max_angle>
          </vertical>
        </scan>
        <range>
          <min>0.3</min>
          <max>131.0</max>
          <resolution>0.001</resolution>
        </range>
        <noise>
          <type>gaussian</type>
          <mean>0.0</mean>
          <stddev>0.0</stddev>
        </noise>
      </ray>
      <plugin filename="libgazebo_ros_velodyne_gpu_laser.so" name="gazebo_ros_laser_controller">
        <topicName>/velodyne_points</topicName>
        <frameName>velodyne</frameName>
        <organize_cloud>False</organize_cloud>
        <min_range>0.9</min_range>
        <max_range>130.0</max_range>
        <gaussianNoise>0.008</gaussianNoise>
      </plugin>
    </sensor>
  </gazebo>
  <!-- laser -->
  <!-- <xacro:include filename="$(find mm_description)/urdf/sensors/laser_sensor.xacro" />
    <xacro:rplidar />
    <joint name="laser_support_joint" type="fixed">
        <origin xyz="0.14 0.0 0.83" rpy="0 0 0" />
        <parent link="support_link" />
        <child link="laser_link" />
    </joint> -->
  <link name="imu_link">
    <inertial>
      <mass value="0.1"/>
      <origin xyz="0 0 0"/>
      <inertia ixx="0.01" ixy="0.0" ixz="0.0" iyy="0.01" iyz="0.0" izz="0.01"/>
    </inertial>
    <visual>
      <origin rpy="0 0 0" xyz=" 0 0 0 "/>
      <geometry>
        <box size="0.02 0.02 0.01"/>
      </geometry>
      <material name="black"/>
    </visual>
    <collision>
      <origin rpy="0 0 0" xyz="0.0 0.0 0.0"/>
      <geometry>
        <box size="0.02 0.02 0.01"/>
      </geometry>
    </collision>
  </link>
  <gazebo reference="imu_link">
    <material>Gazebo/Black</material>
  </gazebo>
  <gazebo reference="imu_link">
    <gravity>true</gravity>
    <sensor name="imu_sensor" type="imu">
      <always_on>true</always_on>
      <update_rate>100</update_rate>
      <visualize>true</visualize>
      <topic>__default_topic__</topic>
      <plugin filename="libgazebo_ros_imu_sensor.so" name="imu_plugin">
        <topicName>imu/data</topicName>
        <bodyName>imu_link</bodyName>
        <updateRateHZ>110.0</updateRateHZ>
        <gaussianNoise>0.0</gaussianNoise>
        <xyzOffset>0 0 0</xyzOffset>
        <rpyOffset>0 0 0</rpyOffset>
        <frameName>imu_link</frameName>
        <initialOrientationAsReference>false</initialOrientationAsReference>
      </plugin>
      <pose>0 0 0 0 0 0</pose>
    </sensor>
  </gazebo>
  <joint name="imu_joint" type="fixed">
    <origin rpy="0 0 0" xyz="0  0  0.32"/>
    <parent link="vehicle_base_link"/>
    <child link="imu_link"/>
  </joint>
  <gazebo>
    <plugin filename="libgazebo_ros_p3d.so" name="p3d_base_controller">
      <alwaysOn>true</alwaysOn>
      <updateRate>200.0</updateRate>
      <bodyName>vehicle_base_link</bodyName>
      <topicName>ls_odom_gt</topicName>
      <gaussianNoise>0.0</gaussianNoise>
      <frameName>world</frameName>
      <xyzOffsets>0 0 0</xyzOffsets>
      <rpyOffsets>0 0 0</rpyOffsets>
    </plugin>
  </gazebo>
</robot>

